<?xml version="1.0"?>
<robot name="simple_lidar_bot" xmlns:xacro="http://www.ros.org/wiki/xacro">
  <xacro:property name="base_length" value="0.42"/>
  <xacro:property name="base_width" value="0.32"/>
  <xacro:property name="base_height" value="0.16"/>
  <xacro:property name="wheel_radius" value="0.07"/>
  <xacro:property name="wheel_width" value="0.045"/>
  <xacro:property name="wheel_y" value="0.19"/>
  <xacro:property name="wheel_x" value="0.0"/>
  <xacro:property name="wheel_z" value="0.07"/>
  <xacro:arg name="publish_odom_tf" default="true"/>

  <link name="base_link">
    <inertial>
      <origin xyz="0 0 0.08"/>
      <mass value="8.0"/>
      <inertia ixx="0.089" ixy="0.0" ixz="0.0" iyy="0.137" iyz="0.0" izz="0.173"/>
    </inertial>
    <visual>
      <origin xyz="0 0 0.08"/>
      <geometry>
        <box size="${base_length} ${base_width} ${base_height}"/>
      </geometry>
      <material name="blue">
        <color rgba="0.1 0.35 0.8 1.0"/>
      </material>
    </visual>
    <collision>
      <origin xyz="0 0 0.08"/>
      <geometry>
        <box size="${base_length} ${base_width} ${base_height}"/>
      </geometry>
    </collision>
  </link>

  <link name="left_wheel_link">
    <inertial>
      <mass value="0.5"/>
      <inertia ixx="0.00036" ixy="0.0" ixz="0.0" iyy="0.00036" iyz="0.0" izz="0.00062"/>
    </inertial>
    <visual>
      <origin rpy="1.57079632679 0 0"/>
      <geometry>
        <cylinder radius="${wheel_radius}" length="${wheel_width}"/>
      </geometry>
      <material name="dark_gray">
        <color rgba="0.05 0.05 0.05 1.0"/>
      </material>
    </visual>
    <collision>
      <origin rpy="1.57079632679 0 0"/>
      <geometry>
        <cylinder radius="${wheel_radius}" length="${wheel_width}"/>
      </geometry>
    </collision>
  </link>

  <link name="right_wheel_link">
    <inertial>
      <mass value="0.5"/>
      <inertia ixx="0.00036" ixy="0.0" ixz="0.0" iyy="0.00036" iyz="0.0" izz="0.00062"/>
    </inertial>
    <visual>
      <origin rpy="1.57079632679 0 0"/>
      <geometry>
        <cylinder radius="${wheel_radius}" length="${wheel_width}"/>
      </geometry>
      <material name="dark_gray"/>
    </visual>
    <collision>
      <origin rpy="1.57079632679 0 0"/>
      <geometry>
        <cylinder radius="${wheel_radius}" length="${wheel_width}"/>
      </geometry>
    </collision>
  </link>

  <link name="caster_link">
    <inertial>
      <mass value="0.1"/>
      <inertia ixx="0.00002" ixy="0.0" ixz="0.0" iyy="0.00002" iyz="0.0" izz="0.00002"/>
    </inertial>
    <visual>
      <geometry>
        <sphere radius="0.035"/>
      </geometry>
      <material name="light_gray">
        <color rgba="0.65 0.65 0.65 1.0"/>
      </material>
    </visual>
    <collision>
      <geometry>
        <sphere radius="0.035"/>
      </geometry>
    </collision>
  </link>

  <link name="laser">
    <inertial>
      <mass value="0.15"/>
      <inertia ixx="0.00012" ixy="0.0" ixz="0.0" iyy="0.00012" iyz="0.0" izz="0.00012"/>
    </inertial>
    <visual>
      <geometry>
        <cylinder radius="0.055" length="0.05"/>
      </geometry>
      <material name="black">
        <color rgba="0.0 0.0 0.0 1.0"/>
      </material>
    </visual>
    <collision>
      <geometry>
        <cylinder radius="0.055" length="0.05"/>
      </geometry>
    </collision>
  </link>

  <link name="imu_link">
    <inertial>
      <mass value="0.05"/>
      <inertia ixx="0.00001" ixy="0.0" ixz="0.0" iyy="0.00001" iyz="0.0" izz="0.00001"/>
    </inertial>
    <visual>
      <geometry>
        <box size="0.05 0.035 0.02"/>
      </geometry>
      <material name="green">
        <color rgba="0.1 0.6 0.2 1.0"/>
      </material>
    </visual>
    <collision>
      <geometry>
        <box size="0.05 0.035 0.02"/>
      </geometry>
    </collision>
  </link>

  <joint name="left_wheel_joint" type="continuous">
    <parent link="base_link"/>
    <child link="left_wheel_link"/>
    <origin xyz="${wheel_x} ${wheel_y} ${wheel_z}"/>
    <axis xyz="0 1 0"/>
  </joint>

  <joint name="right_wheel_joint" type="continuous">
    <parent link="base_link"/>
    <child link="right_wheel_link"/>
    <origin xyz="${wheel_x} -${wheel_y} ${wheel_z}"/>
    <axis xyz="0 1 0"/>
  </joint>

  <joint name="caster_joint" type="fixed">
    <parent link="base_link"/>
    <child link="caster_link"/>
    <origin xyz="-0.16 0 0.035"/>
  </joint>

  <joint name="laser_joint" type="fixed">
    <parent link="base_link"/>
    <child link="laser"/>
    <origin xyz="0.12 0 0.22"/>
  </joint>

  <joint name="imu_joint" type="fixed">
    <parent link="base_link"/>
    <child link="imu_link"/>
    <origin xyz="0 0 0.16"/>
  </joint>

  <gazebo reference="base_link">
    <material>Gazebo/Blue</material>
  </gazebo>

  <gazebo reference="left_wheel_link">
    <material>Gazebo/Black</material>
    <mu1>1.0</mu1>
    <mu2>1.0</mu2>
  </gazebo>

  <gazebo reference="right_wheel_link">
    <material>Gazebo/Black</material>
    <mu1>1.0</mu1>
    <mu2>1.0</mu2>
  </gazebo>

  <gazebo reference="laser">
    <sensor name="scan_raw_sensor" type="ray">
      <always_on>true</always_on>
      <visualize>false</visualize>
      <update_rate>10.0</update_rate>
      <ray>
        <scan>
          <horizontal>
            <samples>360</samples>
            <resolution>1</resolution>
            <min_angle>-3.14159265359</min_angle>
            <max_angle>3.14159265359</max_angle>
          </horizontal>
        </scan>
        <range>
          <min>0.12</min>
          <max>8.0</max>
          <resolution>0.01</resolution>
        </range>
        <noise>
          <type>gaussian</type>
          <mean>0.0</mean>
          <stddev>0.0</stddev>
        </noise>
      </ray>
      <plugin name="scan_raw_plugin" filename="libgazebo_ros_ray_sensor.so">
        <ros>
          <remapping>~/out:=scan_raw</remapping>
        </ros>
        <output_type>sensor_msgs/LaserScan</output_type>
        <frame_name>laser</frame_name>
      </plugin>
    </sensor>
  </gazebo>

  <gazebo reference="imu_link">
    <sensor name="imu_sensor" type="imu">
      <always_on>true</always_on>
      <visualize>false</visualize>
      <update_rate>50.0</update_rate>
      <plugin name="imu_plugin" filename="libgazebo_ros_imu_sensor.so">
        <ros>
          <remapping>~/out:=imu/data</remapping>
        </ros>
        <frame_name>imu_link</frame_name>
        <initial_orientation_as_reference>false</initial_orientation_as_reference>
      </plugin>
    </sensor>
  </gazebo>

  <gazebo>
    <plugin name="diff_drive_plugin" filename="libgazebo_ros_diff_drive.so">
      <ros>
        <namespace>/</namespace>
      </ros>
      <update_rate>30.0</update_rate>
      <left_joint>left_wheel_joint</left_joint>
      <right_joint>right_wheel_joint</right_joint>
      <wheel_separation>0.38</wheel_separation>
      <wheel_diameter>0.14</wheel_diameter>
      <max_wheel_torque>20.0</max_wheel_torque>
      <max_wheel_acceleration>2.0</max_wheel_acceleration>
      <command_topic>cmd_vel</command_topic>
      <odometry_topic>odom</odometry_topic>
      <odometry_frame>odom</odometry_frame>
      <robot_base_frame>base_link</robot_base_frame>
      <publish_odom>true</publish_odom>
      <publish_odom_tf>$(arg publish_odom_tf)</publish_odom_tf>
      <publish_wheel_tf>false</publish_wheel_tf>
    </plugin>

    <plugin name="joint_state_plugin" filename="libgazebo_ros_joint_state_publisher.so">
      <update_rate>30.0</update_rate>
      <joint_name>left_wheel_joint</joint_name>
      <joint_name>right_wheel_joint</joint_name>
    </plugin>

    <plugin name="ground_truth_p3d" filename="libgazebo_ros_p3d.so">
      <ros>
        <namespace>/ground_truth</namespace>
        <remapping>odom:=odom</remapping>
      </ros>
      <body_name>base_link</body_name>
      <frame_name>odom</frame_name>
      <update_rate>30.0</update_rate>
    </plugin>
  </gazebo>
</robot>
